2024-02-12 16:50:51 ERROR 400 response executing GraphQL.
2024-02-12 16:50:51 ERROR {"errors":[{"message":"name required for project query","path":["project"]}],"data":{"project":null}}
2024-02-12 16:50:51 ERROR Traceback (most recent call last):
  File "C:\Users\khali\OneDrive - Danmarks Tekniske Universitet\conda_envs\ml_ops\lib\site-packages\wandb\apis\normalize.py", line 41, in wrapper
    return func(*args, **kwargs)
  File "C:\Users\khali\OneDrive - Danmarks Tekniske Universitet\conda_envs\ml_ops\lib\site-packages\wandb\sdk\internal\internal_api.py", line 1055, in sweep
    response = self.gql(
  File "C:\Users\khali\OneDrive - Danmarks Tekniske Universitet\conda_envs\ml_ops\lib\site-packages\wandb\sdk\internal\internal_api.py", line 341, in gql
    ret = self._retry_gql(
  File "C:\Users\khali\OneDrive - Danmarks Tekniske Universitet\conda_envs\ml_ops\lib\site-packages\wandb\sdk\lib\retry.py", line 131, in __call__
    result = self._call_fn(*args, **kwargs)
  File "C:\Users\khali\OneDrive - Danmarks Tekniske Universitet\conda_envs\ml_ops\lib\site-packages\wandb\sdk\internal\internal_api.py", line 369, in execute
    return self.client.execute(*args, **kwargs)  # type: ignore
  File "C:\Users\khali\OneDrive - Danmarks Tekniske Universitet\conda_envs\ml_ops\lib\site-packages\wandb\vendor\gql-0.2.0\wandb_gql\client.py", line 52, in execute
    result = self._get_result(document, *args, **kwargs)
  File "C:\Users\khali\OneDrive - Danmarks Tekniske Universitet\conda_envs\ml_ops\lib\site-packages\wandb\vendor\gql-0.2.0\wandb_gql\client.py", line 60, in _get_result
    return self.transport.execute(document, *args, **kwargs)
  File "C:\Users\khali\OneDrive - Danmarks Tekniske Universitet\conda_envs\ml_ops\lib\site-packages\wandb\sdk\lib\gql_request.py", line 59, in execute
    request.raise_for_status()
  File "C:\Users\khali\OneDrive - Danmarks Tekniske Universitet\conda_envs\ml_ops\lib\site-packages\requests\models.py", line 1021, in raise_for_status
    raise HTTPError(http_error_msg, response=self)
requests.exceptions.HTTPError: 400 Client Error: Bad Request for url: https://api.wandb.ai/graphql

During handling of the above exception, another exception occurred:

Traceback (most recent call last):
  File "C:\Users\khali\OneDrive - Danmarks Tekniske Universitet\conda_envs\ml_ops\lib\site-packages\wandb\cli\cli.py", line 105, in wrapper
    return func(*args, **kwargs)
  File "C:\Users\khali\OneDrive - Danmarks Tekniske Universitet\conda_envs\ml_ops\lib\site-packages\wandb\cli\cli.py", line 1731, in agent
    wandb_agent.agent(sweep_id, entity=entity, project=project, count=count)
  File "C:\Users\khali\OneDrive - Danmarks Tekniske Universitet\conda_envs\ml_ops\lib\site-packages\wandb\wandb_agent.py", line 583, in agent
    return run_agent(
  File "C:\Users\khali\OneDrive - Danmarks Tekniske Universitet\conda_envs\ml_ops\lib\site-packages\wandb\wandb_agent.py", line 528, in run_agent
    agent.run()
  File "C:\Users\khali\OneDrive - Danmarks Tekniske Universitet\conda_envs\ml_ops\lib\site-packages\wandb\wandb_agent.py", line 190, in run
    sweep_obj = self._api.sweep(self._sweep_id, "{}")
  File "C:\Users\khali\OneDrive - Danmarks Tekniske Universitet\conda_envs\ml_ops\lib\site-packages\wandb\apis\internal.py", line 126, in sweep
    return self.api.sweep(*args, **kwargs)
  File "C:\Users\khali\OneDrive - Danmarks Tekniske Universitet\conda_envs\ml_ops\lib\site-packages\wandb\apis\normalize.py", line 51, in wrapper
    raise CommError(message, error)
wandb.errors.CommError: name required for project query (Error 400: Bad Request)

2024-02-12 16:54:08 ERROR 400 response executing GraphQL.
2024-02-12 16:54:08 ERROR {"errors":[{"message":"name required for project query","path":["project"]}],"data":{"project":null}}
2024-02-12 16:54:08 ERROR Traceback (most recent call last):
  File "C:\Users\khali\OneDrive - Danmarks Tekniske Universitet\conda_envs\ml_ops\lib\site-packages\wandb\apis\normalize.py", line 41, in wrapper
    return func(*args, **kwargs)
  File "C:\Users\khali\OneDrive - Danmarks Tekniske Universitet\conda_envs\ml_ops\lib\site-packages\wandb\sdk\internal\internal_api.py", line 1055, in sweep
    response = self.gql(
  File "C:\Users\khali\OneDrive - Danmarks Tekniske Universitet\conda_envs\ml_ops\lib\site-packages\wandb\sdk\internal\internal_api.py", line 341, in gql
    ret = self._retry_gql(
  File "C:\Users\khali\OneDrive - Danmarks Tekniske Universitet\conda_envs\ml_ops\lib\site-packages\wandb\sdk\lib\retry.py", line 131, in __call__
    result = self._call_fn(*args, **kwargs)
  File "C:\Users\khali\OneDrive - Danmarks Tekniske Universitet\conda_envs\ml_ops\lib\site-packages\wandb\sdk\internal\internal_api.py", line 369, in execute
    return self.client.execute(*args, **kwargs)  # type: ignore
  File "C:\Users\khali\OneDrive - Danmarks Tekniske Universitet\conda_envs\ml_ops\lib\site-packages\wandb\vendor\gql-0.2.0\wandb_gql\client.py", line 52, in execute
    result = self._get_result(document, *args, **kwargs)
  File "C:\Users\khali\OneDrive - Danmarks Tekniske Universitet\conda_envs\ml_ops\lib\site-packages\wandb\vendor\gql-0.2.0\wandb_gql\client.py", line 60, in _get_result
    return self.transport.execute(document, *args, **kwargs)
  File "C:\Users\khali\OneDrive - Danmarks Tekniske Universitet\conda_envs\ml_ops\lib\site-packages\wandb\sdk\lib\gql_request.py", line 59, in execute
    request.raise_for_status()
  File "C:\Users\khali\OneDrive - Danmarks Tekniske Universitet\conda_envs\ml_ops\lib\site-packages\requests\models.py", line 1021, in raise_for_status
    raise HTTPError(http_error_msg, response=self)
requests.exceptions.HTTPError: 400 Client Error: Bad Request for url: https://api.wandb.ai/graphql

During handling of the above exception, another exception occurred:

Traceback (most recent call last):
  File "C:\Users\khali\OneDrive - Danmarks Tekniske Universitet\conda_envs\ml_ops\lib\site-packages\wandb\cli\cli.py", line 105, in wrapper
    return func(*args, **kwargs)
  File "C:\Users\khali\OneDrive - Danmarks Tekniske Universitet\conda_envs\ml_ops\lib\site-packages\wandb\cli\cli.py", line 1731, in agent
    wandb_agent.agent(sweep_id, entity=entity, project=project, count=count)
  File "C:\Users\khali\OneDrive - Danmarks Tekniske Universitet\conda_envs\ml_ops\lib\site-packages\wandb\wandb_agent.py", line 583, in agent
    return run_agent(
  File "C:\Users\khali\OneDrive - Danmarks Tekniske Universitet\conda_envs\ml_ops\lib\site-packages\wandb\wandb_agent.py", line 528, in run_agent
    agent.run()
  File "C:\Users\khali\OneDrive - Danmarks Tekniske Universitet\conda_envs\ml_ops\lib\site-packages\wandb\wandb_agent.py", line 190, in run
    sweep_obj = self._api.sweep(self._sweep_id, "{}")
  File "C:\Users\khali\OneDrive - Danmarks Tekniske Universitet\conda_envs\ml_ops\lib\site-packages\wandb\apis\internal.py", line 126, in sweep
    return self.api.sweep(*args, **kwargs)
  File "C:\Users\khali\OneDrive - Danmarks Tekniske Universitet\conda_envs\ml_ops\lib\site-packages\wandb\apis\normalize.py", line 51, in wrapper
    raise CommError(message, error)
wandb.errors.CommError: name required for project query (Error 400: Bad Request)

2024-02-12 16:55:45 ERROR 400 response executing GraphQL.
2024-02-12 16:55:45 ERROR {"errors":[{"message":"name required for project query","path":["project"]}],"data":{"project":null}}
2024-02-12 16:55:45 ERROR Traceback (most recent call last):
  File "C:\Users\khali\OneDrive - Danmarks Tekniske Universitet\conda_envs\ml_ops\lib\site-packages\wandb\apis\normalize.py", line 41, in wrapper
    return func(*args, **kwargs)
  File "C:\Users\khali\OneDrive - Danmarks Tekniske Universitet\conda_envs\ml_ops\lib\site-packages\wandb\sdk\internal\internal_api.py", line 1055, in sweep
    response = self.gql(
  File "C:\Users\khali\OneDrive - Danmarks Tekniske Universitet\conda_envs\ml_ops\lib\site-packages\wandb\sdk\internal\internal_api.py", line 341, in gql
    ret = self._retry_gql(
  File "C:\Users\khali\OneDrive - Danmarks Tekniske Universitet\conda_envs\ml_ops\lib\site-packages\wandb\sdk\lib\retry.py", line 131, in __call__
    result = self._call_fn(*args, **kwargs)
  File "C:\Users\khali\OneDrive - Danmarks Tekniske Universitet\conda_envs\ml_ops\lib\site-packages\wandb\sdk\internal\internal_api.py", line 369, in execute
    return self.client.execute(*args, **kwargs)  # type: ignore
  File "C:\Users\khali\OneDrive - Danmarks Tekniske Universitet\conda_envs\ml_ops\lib\site-packages\wandb\vendor\gql-0.2.0\wandb_gql\client.py", line 52, in execute
    result = self._get_result(document, *args, **kwargs)
  File "C:\Users\khali\OneDrive - Danmarks Tekniske Universitet\conda_envs\ml_ops\lib\site-packages\wandb\vendor\gql-0.2.0\wandb_gql\client.py", line 60, in _get_result
    return self.transport.execute(document, *args, **kwargs)
  File "C:\Users\khali\OneDrive - Danmarks Tekniske Universitet\conda_envs\ml_ops\lib\site-packages\wandb\sdk\lib\gql_request.py", line 59, in execute
    request.raise_for_status()
  File "C:\Users\khali\OneDrive - Danmarks Tekniske Universitet\conda_envs\ml_ops\lib\site-packages\requests\models.py", line 1021, in raise_for_status
    raise HTTPError(http_error_msg, response=self)
requests.exceptions.HTTPError: 400 Client Error: Bad Request for url: https://api.wandb.ai/graphql

During handling of the above exception, another exception occurred:

Traceback (most recent call last):
  File "C:\Users\khali\OneDrive - Danmarks Tekniske Universitet\conda_envs\ml_ops\lib\site-packages\wandb\cli\cli.py", line 105, in wrapper
    return func(*args, **kwargs)
  File "C:\Users\khali\OneDrive - Danmarks Tekniske Universitet\conda_envs\ml_ops\lib\site-packages\wandb\cli\cli.py", line 1731, in agent
    wandb_agent.agent(sweep_id, entity=entity, project=project, count=count)
  File "C:\Users\khali\OneDrive - Danmarks Tekniske Universitet\conda_envs\ml_ops\lib\site-packages\wandb\wandb_agent.py", line 583, in agent
    return run_agent(
  File "C:\Users\khali\OneDrive - Danmarks Tekniske Universitet\conda_envs\ml_ops\lib\site-packages\wandb\wandb_agent.py", line 528, in run_agent
    agent.run()
  File "C:\Users\khali\OneDrive - Danmarks Tekniske Universitet\conda_envs\ml_ops\lib\site-packages\wandb\wandb_agent.py", line 190, in run
    sweep_obj = self._api.sweep(self._sweep_id, "{}")
  File "C:\Users\khali\OneDrive - Danmarks Tekniske Universitet\conda_envs\ml_ops\lib\site-packages\wandb\apis\internal.py", line 126, in sweep
    return self.api.sweep(*args, **kwargs)
  File "C:\Users\khali\OneDrive - Danmarks Tekniske Universitet\conda_envs\ml_ops\lib\site-packages\wandb\apis\normalize.py", line 51, in wrapper
    raise CommError(message, error)
wandb.errors.CommError: name required for project query (Error 400: Bad Request)

2024-02-12 16:58:32 ERROR Traceback (most recent call last):
  File "C:\Users\khali\OneDrive - Danmarks Tekniske Universitet\conda_envs\ml_ops\lib\site-packages\wandb\apis\normalize.py", line 41, in wrapper
    return func(*args, **kwargs)
  File "C:\Users\khali\OneDrive - Danmarks Tekniske Universitet\conda_envs\ml_ops\lib\site-packages\wandb\sdk\internal\internal_api.py", line 1065, in sweep
    raise ValueError(f"Sweep {entity}/{project}/{sweep} not found")
ValueError: Sweep khali/text_classification/tqqvy5jp not found

During handling of the above exception, another exception occurred:

Traceback (most recent call last):
  File "C:\Users\khali\OneDrive - Danmarks Tekniske Universitet\conda_envs\ml_ops\lib\site-packages\wandb\cli\cli.py", line 105, in wrapper
    return func(*args, **kwargs)
  File "C:\Users\khali\OneDrive - Danmarks Tekniske Universitet\conda_envs\ml_ops\lib\site-packages\wandb\cli\cli.py", line 1731, in agent
    wandb_agent.agent(sweep_id, entity=entity, project=project, count=count)
  File "C:\Users\khali\OneDrive - Danmarks Tekniske Universitet\conda_envs\ml_ops\lib\site-packages\wandb\wandb_agent.py", line 583, in agent
    return run_agent(
  File "C:\Users\khali\OneDrive - Danmarks Tekniske Universitet\conda_envs\ml_ops\lib\site-packages\wandb\wandb_agent.py", line 528, in run_agent
    agent.run()
  File "C:\Users\khali\OneDrive - Danmarks Tekniske Universitet\conda_envs\ml_ops\lib\site-packages\wandb\wandb_agent.py", line 190, in run
    sweep_obj = self._api.sweep(self._sweep_id, "{}")
  File "C:\Users\khali\OneDrive - Danmarks Tekniske Universitet\conda_envs\ml_ops\lib\site-packages\wandb\apis\internal.py", line 126, in sweep
    return self.api.sweep(*args, **kwargs)
  File "C:\Users\khali\OneDrive - Danmarks Tekniske Universitet\conda_envs\ml_ops\lib\site-packages\wandb\apis\normalize.py", line 87, in wrapper
    raise CommError(message, err).with_traceback(sys.exc_info()[2])
  File "C:\Users\khali\OneDrive - Danmarks Tekniske Universitet\conda_envs\ml_ops\lib\site-packages\wandb\apis\normalize.py", line 41, in wrapper
    return func(*args, **kwargs)
  File "C:\Users\khali\OneDrive - Danmarks Tekniske Universitet\conda_envs\ml_ops\lib\site-packages\wandb\sdk\internal\internal_api.py", line 1065, in sweep
    raise ValueError(f"Sweep {entity}/{project}/{sweep} not found")
wandb.errors.CommError: Sweep khali/text_classification/tqqvy5jp not found

2024-02-12 16:58:53 ERROR 400 response executing GraphQL.
2024-02-12 16:58:53 ERROR {"errors":[{"message":"name required for project query","path":["project"]}],"data":{"project":null}}
2024-02-12 16:58:53 ERROR Traceback (most recent call last):
  File "C:\Users\khali\OneDrive - Danmarks Tekniske Universitet\conda_envs\ml_ops\lib\site-packages\wandb\apis\normalize.py", line 41, in wrapper
    return func(*args, **kwargs)
  File "C:\Users\khali\OneDrive - Danmarks Tekniske Universitet\conda_envs\ml_ops\lib\site-packages\wandb\sdk\internal\internal_api.py", line 1055, in sweep
    response = self.gql(
  File "C:\Users\khali\OneDrive - Danmarks Tekniske Universitet\conda_envs\ml_ops\lib\site-packages\wandb\sdk\internal\internal_api.py", line 341, in gql
    ret = self._retry_gql(
  File "C:\Users\khali\OneDrive - Danmarks Tekniske Universitet\conda_envs\ml_ops\lib\site-packages\wandb\sdk\lib\retry.py", line 131, in __call__
    result = self._call_fn(*args, **kwargs)
  File "C:\Users\khali\OneDrive - Danmarks Tekniske Universitet\conda_envs\ml_ops\lib\site-packages\wandb\sdk\internal\internal_api.py", line 369, in execute
    return self.client.execute(*args, **kwargs)  # type: ignore
  File "C:\Users\khali\OneDrive - Danmarks Tekniske Universitet\conda_envs\ml_ops\lib\site-packages\wandb\vendor\gql-0.2.0\wandb_gql\client.py", line 52, in execute
    result = self._get_result(document, *args, **kwargs)
  File "C:\Users\khali\OneDrive - Danmarks Tekniske Universitet\conda_envs\ml_ops\lib\site-packages\wandb\vendor\gql-0.2.0\wandb_gql\client.py", line 60, in _get_result
    return self.transport.execute(document, *args, **kwargs)
  File "C:\Users\khali\OneDrive - Danmarks Tekniske Universitet\conda_envs\ml_ops\lib\site-packages\wandb\sdk\lib\gql_request.py", line 59, in execute
    request.raise_for_status()
  File "C:\Users\khali\OneDrive - Danmarks Tekniske Universitet\conda_envs\ml_ops\lib\site-packages\requests\models.py", line 1021, in raise_for_status
    raise HTTPError(http_error_msg, response=self)
requests.exceptions.HTTPError: 400 Client Error: Bad Request for url: https://api.wandb.ai/graphql

During handling of the above exception, another exception occurred:

Traceback (most recent call last):
  File "C:\Users\khali\OneDrive - Danmarks Tekniske Universitet\conda_envs\ml_ops\lib\site-packages\wandb\cli\cli.py", line 105, in wrapper
    return func(*args, **kwargs)
  File "C:\Users\khali\OneDrive - Danmarks Tekniske Universitet\conda_envs\ml_ops\lib\site-packages\wandb\cli\cli.py", line 1731, in agent
    wandb_agent.agent(sweep_id, entity=entity, project=project, count=count)
  File "C:\Users\khali\OneDrive - Danmarks Tekniske Universitet\conda_envs\ml_ops\lib\site-packages\wandb\wandb_agent.py", line 583, in agent
    return run_agent(
  File "C:\Users\khali\OneDrive - Danmarks Tekniske Universitet\conda_envs\ml_ops\lib\site-packages\wandb\wandb_agent.py", line 528, in run_agent
    agent.run()
  File "C:\Users\khali\OneDrive - Danmarks Tekniske Universitet\conda_envs\ml_ops\lib\site-packages\wandb\wandb_agent.py", line 190, in run
    sweep_obj = self._api.sweep(self._sweep_id, "{}")
  File "C:\Users\khali\OneDrive - Danmarks Tekniske Universitet\conda_envs\ml_ops\lib\site-packages\wandb\apis\internal.py", line 126, in sweep
    return self.api.sweep(*args, **kwargs)
  File "C:\Users\khali\OneDrive - Danmarks Tekniske Universitet\conda_envs\ml_ops\lib\site-packages\wandb\apis\normalize.py", line 51, in wrapper
    raise CommError(message, error)
wandb.errors.CommError: name required for project query (Error 400: Bad Request)

2024-02-12 17:00:27 ERROR 400 response executing GraphQL.
2024-02-12 17:00:27 ERROR {"errors":[{"message":"name required for project query","path":["project"]}],"data":{"project":null}}
2024-02-12 17:00:27 ERROR Traceback (most recent call last):
  File "C:\Users\khali\OneDrive - Danmarks Tekniske Universitet\conda_envs\ml_ops\lib\site-packages\wandb\apis\normalize.py", line 41, in wrapper
    return func(*args, **kwargs)
  File "C:\Users\khali\OneDrive - Danmarks Tekniske Universitet\conda_envs\ml_ops\lib\site-packages\wandb\sdk\internal\internal_api.py", line 1055, in sweep
    response = self.gql(
  File "C:\Users\khali\OneDrive - Danmarks Tekniske Universitet\conda_envs\ml_ops\lib\site-packages\wandb\sdk\internal\internal_api.py", line 341, in gql
    ret = self._retry_gql(
  File "C:\Users\khali\OneDrive - Danmarks Tekniske Universitet\conda_envs\ml_ops\lib\site-packages\wandb\sdk\lib\retry.py", line 131, in __call__
    result = self._call_fn(*args, **kwargs)
  File "C:\Users\khali\OneDrive - Danmarks Tekniske Universitet\conda_envs\ml_ops\lib\site-packages\wandb\sdk\internal\internal_api.py", line 369, in execute
    return self.client.execute(*args, **kwargs)  # type: ignore
  File "C:\Users\khali\OneDrive - Danmarks Tekniske Universitet\conda_envs\ml_ops\lib\site-packages\wandb\vendor\gql-0.2.0\wandb_gql\client.py", line 52, in execute
    result = self._get_result(document, *args, **kwargs)
  File "C:\Users\khali\OneDrive - Danmarks Tekniske Universitet\conda_envs\ml_ops\lib\site-packages\wandb\vendor\gql-0.2.0\wandb_gql\client.py", line 60, in _get_result
    return self.transport.execute(document, *args, **kwargs)
  File "C:\Users\khali\OneDrive - Danmarks Tekniske Universitet\conda_envs\ml_ops\lib\site-packages\wandb\sdk\lib\gql_request.py", line 59, in execute
    request.raise_for_status()
  File "C:\Users\khali\OneDrive - Danmarks Tekniske Universitet\conda_envs\ml_ops\lib\site-packages\requests\models.py", line 1021, in raise_for_status
    raise HTTPError(http_error_msg, response=self)
requests.exceptions.HTTPError: 400 Client Error: Bad Request for url: https://api.wandb.ai/graphql

During handling of the above exception, another exception occurred:

Traceback (most recent call last):
  File "C:\Users\khali\OneDrive - Danmarks Tekniske Universitet\conda_envs\ml_ops\lib\site-packages\wandb\cli\cli.py", line 105, in wrapper
    return func(*args, **kwargs)
  File "C:\Users\khali\OneDrive - Danmarks Tekniske Universitet\conda_envs\ml_ops\lib\site-packages\wandb\cli\cli.py", line 1731, in agent
    wandb_agent.agent(sweep_id, entity=entity, project=project, count=count)
  File "C:\Users\khali\OneDrive - Danmarks Tekniske Universitet\conda_envs\ml_ops\lib\site-packages\wandb\wandb_agent.py", line 583, in agent
    return run_agent(
  File "C:\Users\khali\OneDrive - Danmarks Tekniske Universitet\conda_envs\ml_ops\lib\site-packages\wandb\wandb_agent.py", line 528, in run_agent
    agent.run()
  File "C:\Users\khali\OneDrive - Danmarks Tekniske Universitet\conda_envs\ml_ops\lib\site-packages\wandb\wandb_agent.py", line 190, in run
    sweep_obj = self._api.sweep(self._sweep_id, "{}")
  File "C:\Users\khali\OneDrive - Danmarks Tekniske Universitet\conda_envs\ml_ops\lib\site-packages\wandb\apis\internal.py", line 126, in sweep
    return self.api.sweep(*args, **kwargs)
  File "C:\Users\khali\OneDrive - Danmarks Tekniske Universitet\conda_envs\ml_ops\lib\site-packages\wandb\apis\normalize.py", line 51, in wrapper
    raise CommError(message, error)
wandb.errors.CommError: name required for project query (Error 400: Bad Request)

2024-02-12 17:04:53 ERROR 400 response executing GraphQL.
2024-02-12 17:04:53 ERROR {"errors":[{"message":"name required for project query","path":["project"]}],"data":{"project":null}}
2024-02-12 17:04:53 ERROR Traceback (most recent call last):
  File "C:\Users\khali\OneDrive - Danmarks Tekniske Universitet\conda_envs\ml_ops\lib\site-packages\wandb\apis\normalize.py", line 41, in wrapper
    return func(*args, **kwargs)
  File "C:\Users\khali\OneDrive - Danmarks Tekniske Universitet\conda_envs\ml_ops\lib\site-packages\wandb\sdk\internal\internal_api.py", line 1055, in sweep
    response = self.gql(
  File "C:\Users\khali\OneDrive - Danmarks Tekniske Universitet\conda_envs\ml_ops\lib\site-packages\wandb\sdk\internal\internal_api.py", line 341, in gql
    ret = self._retry_gql(
  File "C:\Users\khali\OneDrive - Danmarks Tekniske Universitet\conda_envs\ml_ops\lib\site-packages\wandb\sdk\lib\retry.py", line 131, in __call__
    result = self._call_fn(*args, **kwargs)
  File "C:\Users\khali\OneDrive - Danmarks Tekniske Universitet\conda_envs\ml_ops\lib\site-packages\wandb\sdk\internal\internal_api.py", line 369, in execute
    return self.client.execute(*args, **kwargs)  # type: ignore
  File "C:\Users\khali\OneDrive - Danmarks Tekniske Universitet\conda_envs\ml_ops\lib\site-packages\wandb\vendor\gql-0.2.0\wandb_gql\client.py", line 52, in execute
    result = self._get_result(document, *args, **kwargs)
  File "C:\Users\khali\OneDrive - Danmarks Tekniske Universitet\conda_envs\ml_ops\lib\site-packages\wandb\vendor\gql-0.2.0\wandb_gql\client.py", line 60, in _get_result
    return self.transport.execute(document, *args, **kwargs)
  File "C:\Users\khali\OneDrive - Danmarks Tekniske Universitet\conda_envs\ml_ops\lib\site-packages\wandb\sdk\lib\gql_request.py", line 59, in execute
    request.raise_for_status()
  File "C:\Users\khali\OneDrive - Danmarks Tekniske Universitet\conda_envs\ml_ops\lib\site-packages\requests\models.py", line 1021, in raise_for_status
    raise HTTPError(http_error_msg, response=self)
requests.exceptions.HTTPError: 400 Client Error: Bad Request for url: https://api.wandb.ai/graphql

During handling of the above exception, another exception occurred:

Traceback (most recent call last):
  File "C:\Users\khali\OneDrive - Danmarks Tekniske Universitet\conda_envs\ml_ops\lib\site-packages\wandb\cli\cli.py", line 105, in wrapper
    return func(*args, **kwargs)
  File "C:\Users\khali\OneDrive - Danmarks Tekniske Universitet\conda_envs\ml_ops\lib\site-packages\wandb\cli\cli.py", line 1731, in agent
    wandb_agent.agent(sweep_id, entity=entity, project=project, count=count)
  File "C:\Users\khali\OneDrive - Danmarks Tekniske Universitet\conda_envs\ml_ops\lib\site-packages\wandb\wandb_agent.py", line 583, in agent
    return run_agent(
  File "C:\Users\khali\OneDrive - Danmarks Tekniske Universitet\conda_envs\ml_ops\lib\site-packages\wandb\wandb_agent.py", line 528, in run_agent
    agent.run()
  File "C:\Users\khali\OneDrive - Danmarks Tekniske Universitet\conda_envs\ml_ops\lib\site-packages\wandb\wandb_agent.py", line 190, in run
    sweep_obj = self._api.sweep(self._sweep_id, "{}")
  File "C:\Users\khali\OneDrive - Danmarks Tekniske Universitet\conda_envs\ml_ops\lib\site-packages\wandb\apis\internal.py", line 126, in sweep
    return self.api.sweep(*args, **kwargs)
  File "C:\Users\khali\OneDrive - Danmarks Tekniske Universitet\conda_envs\ml_ops\lib\site-packages\wandb\apis\normalize.py", line 51, in wrapper
    raise CommError(message, error)
wandb.errors.CommError: name required for project query (Error 400: Bad Request)

